12:35:52,897 root ERROR Error
Traceback (most recent call last):
  File "/home/romain/Projects/perso/rov-timing-code/src/arin/bot.py", line 196, in <module>
    raise Exception(f'Failed to {args.action} ROA!')
Exception: Failed to delete ROA!
14:47:38,745 root ERROR Error
Traceback (most recent call last):
  File "/home/romain/Projects/perso/rov-timing-code/src/arin/bot.py", line 196, in <module>
    raise Exception(f'Failed to {args.action} ROA!')
Exception: Failed to delete ROA!
01:33:55,31 root ERROR Error
Traceback (most recent call last):
  File "/usr/lib/python3.9/site-packages/urllib3/connection.py", line 174, in _new_conn
    conn = connection.create_connection(
  File "/usr/lib/python3.9/site-packages/urllib3/util/connection.py", line 96, in create_connection
    raise err
  File "/usr/lib/python3.9/site-packages/urllib3/util/connection.py", line 86, in create_connection
    sock.connect(sa)
OSError: [Errno 101] Network is unreachable

During handling of the above exception, another exception occurred:

Traceback (most recent call last):
  File "/usr/lib/python3.9/site-packages/urllib3/connectionpool.py", line 699, in urlopen
    httplib_response = self._make_request(
  File "/usr/lib/python3.9/site-packages/urllib3/connectionpool.py", line 382, in _make_request
    self._validate_conn(conn)
  File "/usr/lib/python3.9/site-packages/urllib3/connectionpool.py", line 1010, in _validate_conn
    conn.connect()
  File "/usr/lib/python3.9/site-packages/urllib3/connection.py", line 358, in connect
    conn = self._new_conn()
  File "/usr/lib/python3.9/site-packages/urllib3/connection.py", line 186, in _new_conn
    raise NewConnectionError(
urllib3.exceptions.NewConnectionError: <urllib3.connection.HTTPSConnection object at 0x7fc01273f070>: Failed to establish a new connection: [Errno 101] Network is unreachable

During handling of the above exception, another exception occurred:

Traceback (most recent call last):
  File "/usr/lib/python3.9/site-packages/requests/adapters.py", line 439, in send
    resp = conn.urlopen(
  File "/usr/lib/python3.9/site-packages/urllib3/connectionpool.py", line 755, in urlopen
    retries = retries.increment(
  File "/usr/lib/python3.9/site-packages/urllib3/util/retry.py", line 574, in increment
    raise MaxRetryError(_pool, url, error or ResponseError(cause))
urllib3.exceptions.MaxRetryError: HTTPSConnectionPool(host='reg.arin.net', port=443): Max retries exceeded with url: /rest/roa/RGNETI-1;resourceClass=AR?apikey=API-85CF-C6D7-421A-843B&format=xml (Caused by NewConnectionError('<urllib3.connection.HTTPSConnection object at 0x7fc01273f070>: Failed to establish a new connection: [Errno 101] Network is unreachable'))

During handling of the above exception, another exception occurred:

Traceback (most recent call last):
  File "/home/romain/Projects/perso/rov-timing-code/src/arin/bot.py", line 191, in <module>
    success = bot.create_roa(args.prefix, args.asn, args.maxPrefixLength)
  File "/home/romain/Projects/perso/rov-timing-code/src/arin/bot.py", line 82, in create_roa
    api_resp = requests.post(
  File "/usr/lib/python3.9/site-packages/requests/api.py", line 117, in post
    return request('post', url, data=data, json=json, **kwargs)
  File "/usr/lib/python3.9/site-packages/requests/api.py", line 61, in request
    return session.request(method=method, url=url, **kwargs)
  File "/usr/lib/python3.9/site-packages/requests/sessions.py", line 542, in request
    resp = self.send(prep, **send_kwargs)
  File "/usr/lib/python3.9/site-packages/requests/sessions.py", line 655, in send
    r = adapter.send(request, **kwargs)
  File "/usr/lib/python3.9/site-packages/requests/adapters.py", line 516, in send
    raise ConnectionError(e, request=request)
requests.exceptions.ConnectionError: HTTPSConnectionPool(host='reg.arin.net', port=443): Max retries exceeded with url: /rest/roa/RGNETI-1;resourceClass=AR?apikey=API-85CF-C6D7-421A-843B&format=xml (Caused by NewConnectionError('<urllib3.connection.HTTPSConnection object at 0x7fc01273f070>: Failed to establish a new connection: [Errno 101] Network is unreachable'))
14:24:43,531 root ERROR Error
Traceback (most recent call last):
  File "/home/romain/Projects/perso/rov-timing-code/src/arin/bot.py", line 196, in <module>
    raise Exception(f'Failed to {args.action} ROA!')
Exception: Failed to delete ROA!
2022-03-11 17:38:13,875 root ERROR Error
Traceback (most recent call last):
  File "/usr/lib/python3.9/site-packages/urllib3/connectionpool.py", line 699, in urlopen
    httplib_response = self._make_request(
  File "/usr/lib/python3.9/site-packages/urllib3/connectionpool.py", line 382, in _make_request
    self._validate_conn(conn)
  File "/usr/lib/python3.9/site-packages/urllib3/connectionpool.py", line 1010, in _validate_conn
    conn.connect()
  File "/usr/lib/python3.9/site-packages/urllib3/connection.py", line 416, in connect
    self.sock = ssl_wrap_socket(
  File "/usr/lib/python3.9/site-packages/urllib3/util/ssl_.py", line 449, in ssl_wrap_socket
    ssl_sock = _ssl_wrap_socket_impl(
  File "/usr/lib/python3.9/site-packages/urllib3/util/ssl_.py", line 493, in _ssl_wrap_socket_impl
    return ssl_context.wrap_socket(sock, server_hostname=server_hostname)
  File "/usr/lib/python3.9/ssl.py", line 500, in wrap_socket
    return self.sslsocket_class._create(
  File "/usr/lib/python3.9/ssl.py", line 1040, in _create
    self.do_handshake()
  File "/usr/lib/python3.9/ssl.py", line 1309, in do_handshake
    self._sslobj.do_handshake()
ConnectionResetError: [Errno 104] Connection reset by peer

During handling of the above exception, another exception occurred:

Traceback (most recent call last):
  File "/usr/lib/python3.9/site-packages/requests/adapters.py", line 439, in send
    resp = conn.urlopen(
  File "/usr/lib/python3.9/site-packages/urllib3/connectionpool.py", line 755, in urlopen
    retries = retries.increment(
  File "/usr/lib/python3.9/site-packages/urllib3/util/retry.py", line 532, in increment
    raise six.reraise(type(error), error, _stacktrace)
  File "/usr/lib/python3.9/site-packages/urllib3/packages/six.py", line 769, in reraise
    raise value.with_traceback(tb)
  File "/usr/lib/python3.9/site-packages/urllib3/connectionpool.py", line 699, in urlopen
    httplib_response = self._make_request(
  File "/usr/lib/python3.9/site-packages/urllib3/connectionpool.py", line 382, in _make_request
    self._validate_conn(conn)
  File "/usr/lib/python3.9/site-packages/urllib3/connectionpool.py", line 1010, in _validate_conn
    conn.connect()
  File "/usr/lib/python3.9/site-packages/urllib3/connection.py", line 416, in connect
    self.sock = ssl_wrap_socket(
  File "/usr/lib/python3.9/site-packages/urllib3/util/ssl_.py", line 449, in ssl_wrap_socket
    ssl_sock = _ssl_wrap_socket_impl(
  File "/usr/lib/python3.9/site-packages/urllib3/util/ssl_.py", line 493, in _ssl_wrap_socket_impl
    return ssl_context.wrap_socket(sock, server_hostname=server_hostname)
  File "/usr/lib/python3.9/ssl.py", line 500, in wrap_socket
    return self.sslsocket_class._create(
  File "/usr/lib/python3.9/ssl.py", line 1040, in _create
    self.do_handshake()
  File "/usr/lib/python3.9/ssl.py", line 1309, in do_handshake
    self._sslobj.do_handshake()
urllib3.exceptions.ProtocolError: ('Connection aborted.', ConnectionResetError(104, 'Connection reset by peer'))

During handling of the above exception, another exception occurred:

Traceback (most recent call last):
  File "/home/romain/Projects/perso/rov-timing-code/src/arin/bot.py", line 193, in <module>
    success = bot.delete_roa(args.prefix, args.asn)
  File "/home/romain/Projects/perso/rov-timing-code/src/arin/bot.py", line 137, in delete_roa
    api_resp = requests.delete(
  File "/usr/lib/python3.9/site-packages/requests/api.py", line 159, in delete
    return request('delete', url, **kwargs)
  File "/usr/lib/python3.9/site-packages/requests/api.py", line 61, in request
    return session.request(method=method, url=url, **kwargs)
  File "/usr/lib/python3.9/site-packages/requests/sessions.py", line 542, in request
    resp = self.send(prep, **send_kwargs)
  File "/usr/lib/python3.9/site-packages/requests/sessions.py", line 655, in send
    r = adapter.send(request, **kwargs)
  File "/usr/lib/python3.9/site-packages/requests/adapters.py", line 498, in send
    raise ConnectionError(err, request=request)
requests.exceptions.ConnectionError: ('Connection aborted.', ConnectionResetError(104, 'Connection reset by peer'))
